Workbook
Name tb_baseline: baseline!$A$1:$H$163
Name tb_baseline: 'baseline V3'!$A$1:$H$163
Name tb_baseline: baseline!$A$1:$H$163
Name tb_baseline: baseline!$A$1:$H$163
Name tb_baseline: 'baseline v4'!$A$1:$H$163
Name tb_sprintday: sprintday!$A$5:$G$32

Sheet dashboard v1
A1: Baseline VS Activity
A2: Activity

Sheet Baseline V1
A1: Actual | B1: =AVERAGE(H7:H28) -> 0.42727273 | I1: Year 2026
A2: Plan | B2: {=AVERAGE(_xlfn.MAP(D7:D28, E7:E28, _xlfn.LAMBDA(_xlpm.s,_xlpm.e, IF(TODAY() > _xlpm.e, 1, IF(TODAY() < _xlpm.s, 0, (TODAY() - _xlpm.s) / (_xlpm.e - _xlpm.s))))))} -> 0.75619835 | I2: Jan | M2: Feb | Q2: Mar | V2: Apr | Z2: May | AD2: Jun | AI2: Jul | AM2: Aug | AR2: Sep | AV2: Oct | AZ2: Nov | BE2: Dec
A3: Varience | B3: =IF(B1<B2,"behide","advance") -> behide | I3: 1 | J3: 1 | K3: 1 | L3: 1 | M3: 2 | N3: 2 | O3: 2 | P3: 2 | Q3: 3 | R3: 3 | S3: 3 | T3: 3 | U3: 3 | V3: 4 | W3: 4 | X3: 4 | Y3: 4 | Z3: 5 | AA3: 5 | AB3: 5 | AC3: 5 | AD3: 6 | AE3: 6 | AF3: 6 | AG3: 6 | AH3: 6 | AI3: 7 | AJ3: 7 | AK3: 7 | AL3: 7 | AM3: 8 | AN3: 8 | AO3: 8 | AP3: 8 | AQ3: 8 | AR3: 9 | AS3: 9 | AT3: 9 | AU3: 9 | AV3: 10 | AW3: 10 | AX3: 10 | AY3: 10 | AZ3: 11 | BA3: 11 | BB3: 11 | BC3: 11 | BD3: 11 | BE3: 12 | BF3: 12 | BG3: 12 | BH3: 12
I4: =DATE(2026, I$3, I5) -> 46027 | J4: =DATE(2026, J$3, J5) -> 46034 | K4: =DATE(2026, K$3, K5) -> 46041 | L4: =DATE(2026, L$3, L5) -> 46048 | M4: =DATE(2026, M$3, M5) -> 46055 | N4: =DATE(2026, N$3, N5) -> 46062 | O4: =DATE(2026, O$3, O5) -> 46069 | P4: =DATE(2026, P$3, P5) -> 46076 | ... BH4: =DATE(2026, BH$3, BH5) -> 46384
I5: 5 | J5: 12 | K5: 19 | L5: 26 | M5: 2 | N5: 9 | O5: 16 | P5: 23 | Q5: 2 | R5: 9 | S5: 16 | T5: 23 | U5: 30 | V5: 6 | W5: 13 | X5: 20 | Y5: 27 | Z5: 4 | AA5: 11 | AB5: 18 | AC5: 25 | AD5: 1 | AE5: 8 | AF5: 15 | AG5: 22 | AH5: 29 | AI5: 6 | AJ5: 13 | AK5: 20 | AL5: 27 | AM5: 3 | AN5: 10 | AO5: 17 | AP5: 24 | AQ5: 31 | AR5: 7 | AS5: 14 | AT5: 21 | AU5: 28 | AV5: 5 | AW5: 12 | AX5: 19 | AY5: 26 | AZ5: 2 | BA5: 9 | BB5: 16 | BC5: 23 | BD5: 30 | BE5: 7 | BF5: 14 | BG5: 21 | BH5: 28
A6: module | B6: feature | C6: story id | D6: start | E6: end | F6: sprint no. | G6: % plan | H6: % actual
A7: MVP1 | B7: User Authentication | C7: S1: Login/Signup | D7: 46027 | E7: 46038 | F7: Sprint 1 | G7: =IF(TODAY() > E7, 1, IF(TODAY() < D7, 0, (TODAY() - D7) / (E7 - D7))) -> 1 | H7: 1
C8: S1: Login/Signup | D8: 46027 | E8: 46038 | F8: Sprint 1 | G8: =IF(TODAY() > E8, 1, IF(TODAY() < D8, 0, (TODAY() - D8) / (E8 - D8))) -> 1 | H8: 1
C9: S2: Profile Management | D9: 46041 | E9: 46052 | F9: Sprint 2 | G9: =IF(TODAY() > E9, 1, IF(TODAY() < D9, 0, (TODAY() - D9) / (E9 - D9))) -> 1 | H9: 1
B10: Task Management | C10: S1: Create/Edit Tasks | D10: 46055 | E10: 46066 | F10: Sprint 3 | G10: =IF(TODAY() > E10, 1, IF(TODAY() < D10, 0, (TODAY() - D10) / (E10 - D10))) -> 1 | H10: 1
C11: S2: Priority Labeling | D11: 46069 | E11: 46080 | F11: Sprint 4 | G11: =IF(TODAY() > E11, 1, IF(TODAY() < D11, 0, (TODAY() - D11) / (E11 - D11))) -> 1 | H11: 1
C12: S3: Due Date Reminders | D12: 46083 | E12: 46094 | F12: Sprint 5 | G12: =IF(TODAY() > E12, 1, IF(TODAY() < D12, 0, (TODAY() - D12) / (E12 - D12))) -> 1 | H12: 1
C13: S4: Task Archiving | D13: 46097 | E13: 46108 | F13: Sprint 6 | G13: =IF(TODAY() > E13, 1, IF(TODAY() < D13, 0, (TODAY() - D13) / (E13 - D13))) -> 1 | H13: 1
A14: MVP2 | B14: Calendar Integration | C14: S1: Sync Google/Outlook | D14: 46118 | E14: 46129 | F14: Sprint 7 | G14: =IF(TODAY() > E14, 1, IF(TODAY() < D14, 0, (TODAY() - D14) / (E14 - D14))) -> 1 | H14: 1
C15: S2: Drag-and-Drop Scheduling | D15: 46132 | E15: 46143 | F15: Sprint 8 | G15: =IF(TODAY() > E15, 1, IF(TODAY() < D15, 0, (TODAY() - D15) / (E15 - D15))) -> 1 | H15: 1
C16: S3: Conflict Detection | D16: 46146 | E16: 46157 | F16: Sprint 9 | G16: =IF(TODAY() > E16, 1, IF(TODAY() < D16, 0, (TODAY() - D16) / (E16 - D16))) -> 1 | H16: 0.2
B17: Progress Tracking | C17: S1: Daily Progress Dashboard | D17: 46160 | E17: 46171 | F17: Sprint 10 | G17: =IF(TODAY() > E17, 1, IF(TODAY() < D17, 0, (TODAY() - D17) / (E17 - D17))) -> 1 | H17: 0.1
C18: S2: Weekly Productivity Reports | D18: 46174 | E18: 46185 | F18: Sprint 11 | G18: =IF(TODAY() > E18, 1, IF(TODAY() < D18, 0, (TODAY() - D18) / (E18 - D18))) -> 1 | H18: 0.1
C19: S3: Streak/Gamification | D19: 46188 | E19: 46199 | F19: Sprint 12 | G19: =IF(TODAY() > E19, 1, IF(TODAY() < D19, 0, (TODAY() - D19) / (E19 - D19))) -> 1 | H19: 0
A20: Ph3 | B20: Collaboration | C20: S1: Shared Task Lists | D20: 46209 | E20: 46220 | F20: Sprint 13 | G20: =IF(TODAY() > E20, 1, IF(TODAY() < D20, 0, (TODAY() - D20) / (E20 - D20))) -> 1 | H20: 0
C21: S2: Team Comments/Mentions | D21: 46223 | E21: 46234 | F21: Sprint 14 | G21: =IF(TODAY() > E21, 1, IF(TODAY() < D21, 0, (TODAY() - D21) / (E21 - D21))) -> 1 | H21: 0
C22: S3: Role-based Permissions | D22: 46237 | E22: 46248 | F22: Sprint 15 | G22: =IF(TODAY() > E22, 1, IF(TODAY() < D22, 0, (TODAY() - D22) / (E22 - D22))) -> 1 | H22: 0
B23: Advanced Tools | C23: S1: Pomodoro Timer | D23: 46251 | E23: 46262 | F23: Sprint 16 | G23: =IF(TODAY() > E23, 1, IF(TODAY() < D23, 0, (TODAY() - D23) / (E23 - D23))) -> 0.63636364 | H23: 0
C24: S2: Focus Mode | D24: 46265 | E24: 46276 | F24: Sprint 17 | G24: =IF(TODAY() > E24, 1, IF(TODAY() < D24, 0, (TODAY() - D24) / (E24 - D24))) -> 0 | H24: 0
A25: QA/Go-Live | B25: Final Stabilization | C25: S1: UAT & Bug Fixing | D25: 46300 | E25: 46311 | F25: Sprint 20 | G25: =IF(TODAY() > E25, 1, IF(TODAY() < D25, 0, (TODAY() - D25) / (E25 - D25))) -> 0 | H25: 0
C26: S2: Performance Tuning | D26: 46314 | E26: 46325 | F26: Sprint 21 | G26: =IF(TODAY() > E26, 1, IF(TODAY() < D26, 0, (TODAY() - D26) / (E26 - D26))) -> 0 | H26: 0
C27: S3: Deployment & Go-Live | D27: 46328 | E27: 46339 | F27: Sprint 22 | G27: =IF(TODAY() > E27, 1, IF(TODAY() < D27, 0, (TODAY() - D27) / (E27 - D27))) -> 0 | H27: 0
B28: Post-Launch | C28: S1: Maintenance & Feedback | D28: 46342 | E28: 46381 | F28: Sprint 23-25 | G28: =IF(TODAY() > E28, 1, IF(TODAY() < D28, 0, (TODAY() - D28) / (E28 - D28))) -> 0 | H28: 0

Sheet Baseline V2
A1: Actual | B1: =AVERAGE(H7:H25) -> 0.599375 | I1: Year 2026
A2: Plan | B2: {=AVERAGE(_xlfn.MAP(D7:D25, E7:E25, _xlfn.LAMBDA(_xlpm.s,_xlpm.e, IF(TODAY() > _xlpm.e, 1, IF(TODAY() < _xlpm.s, 0, (TODAY() - _xlpm.s) / (_xlpm.e - _xlpm.s))))))} -> 1 | I2: Jan | M2: Feb | Q2: Mar | V2: Apr | Z2: May | AD2: Jun | AI2: Jul | AM2: Aug | AR2: Sep | AV2: Oct | AZ2: Nov | BE2: Dec
A3: Varience | B3: =IF(B1<B2,"behide","advance") -> behide | I3: 1 | J3: 1 | K3: 1 | L3: 1 | M3: 2 | N3: 2 | O3: 2 | P3: 2 | Q3: 3 | R3: 3 | S3: 3 | T3: 3 | U3: 3 | V3: 4 | W3: 4 | X3: 4 | Y3: 4 | Z3: 5 | AA3: 5 | AB3: 5 | AC3: 5 | AD3: 6 | AE3: 6 | AF3: 6 | AG3: 6 | AH3: 6 | AI3: 7 | AJ3: 7 | AK3: 7 | AL3: 7 | AM3: 8 | AN3: 8 | AO3: 8 | AP3: 8 | AQ3: 8 | AR3: 9 | AS3: 9 | AT3: 9 | AU3: 9 | AV3: 10 | AW3: 10 | AX3: 10 | AY3: 10 | AZ3: 11 | BA3: 11 | BB3: 11 | BC3: 11 | BD3: 11 | BE3: 12 | BF3: 12 | BG3: 12 | BH3: 12
I4: =DATE(2026, I$3, I5) -> 46027 | J4: =DATE(2026, J$3, J5) -> 46034 | K4: =DATE(2026, K$3, K5) -> 46041 | L4: =DATE(2026, L$3, L5) -> 46048 | M4: =DATE(2026, M$3, M5) -> 46055 | N4: =DATE(2026, N$3, N5) -> 46062 | O4: =DATE(2026, O$3, O5) -> 46069 | P4: =DATE(2026, P$3, P5) -> 46076 | ... BH4: =DATE(2026, BH$3, BH5) -> 46384
I5: 5 | J5: 12 | K5: 19 | L5: 26 | M5: 2 | N5: 9 | O5: 16 | P5: 23 | Q5: 2 | R5: 9 | S5: 16 | T5: 23 | U5: 30 | V5: 6 | W5: 13 | X5: 20 | Y5: 27 | Z5: 4 | AA5: 11 | AB5: 18 | AC5: 25 | AD5: 1 | AE5: 8 | AF5: 15 | AG5: 22 | AH5: 29 | AI5: 6 | AJ5: 13 | AK5: 20 | AL5: 27 | AM5: 3 | AN5: 10 | AO5: 17 | AP5: 24 | AQ5: 31 | AR5: 7 | AS5: 14 | AT5: 21 | AU5: 28 | AV5: 5 | AW5: 12 | AX5: 19 | AY5: 26 | AZ5: 2 | BA5: 9 | BB5: 16 | BC5: 23 | BD5: 30 | BE5: 7 | BF5: 14 | BG5: 21 | BH5: 28
A6: module | B6: feature | C6: story id | D6: start | E6: end | F6: sprint no. | G6: % plan | H6: % actual
A7: MVP1 | D7: 46027 | E7: 46108 | H7: 1
B8: User Authentication | D8: 46027 | E8: 46052 | G8: 1 | H8: 1
C9: S1: Login/Signup | D9: 46027 | E9: 46038 | F9: Sprint 1 | G9: =IF(TODAY() > E9, 1, IF(TODAY() < D9, 0, (TODAY() - D9) / (E9 - D9))) -> 1 | H9: 1
C10: S1: Login/Signup | D10: 46027 | E10: 46038 | F10: Sprint 1 | G10: =IF(TODAY() > E10, 1, IF(TODAY() < D10, 0, (TODAY() - D10) / (E10 - D10))) -> 1 | H10: 1
C11: S2: Profile Management | D11: 46041 | E11: 46052 | F11: Sprint 2 | G11: =IF(TODAY() > E11, 1, IF(TODAY() < D11, 0, (TODAY() - D11) / (E11 - D11))) -> 1 | H11: 1
B12: Task Management | D12: 46055 | E12: 46108 | G12: 0.49 | H12: 0.5
C13: S1: Create/Edit Tasks | D13: 46055 | E13: 46066 | F13: Sprint 3 | G13: =IF(TODAY() > E13, 1, IF(TODAY() < D13, 0, (TODAY() - D13) / (E13 - D13))) -> 1 | H13: 0.5
C14: S2: Priority Labeling | D14: 46069 | E14: 46080 | F14: Sprint 4 | G14: =IF(TODAY() > E14, 1, IF(TODAY() < D14, 0, (TODAY() - D14) / (E14 - D14))) -> 1 | H14: 0.5
C15: S3: Due Date Reminders | D15: 46083 | E15: 46094 | F15: Sprint 5 | G15: =IF(TODAY() > E15, 1, IF(TODAY() < D15, 0, (TODAY() - D15) / (E15 - D15))) -> 1 | H15: 0.5
C16: S4: Task Archiving | D16: 46097 | E16: 46108 | F16: Sprint 6 | G16: =IF(TODAY() > E16, 1, IF(TODAY() < D16, 0, (TODAY() - D16) / (E16 - D16))) -> 1 | H16: 0.5
A17: MVP2 | D17: 46118 | E17: 46199
B18: Calendar Integration | D18: 46118 | E18: 46157
C19: S1: Sync Google/Outlook | D19: 46118 | E19: 46129 | F19: Sprint 7 | G19: =IF(TODAY() > E19, 1, IF(TODAY() < D19, 0, (TODAY() - D19) / (E19 - D19))) -> 1 | H19: 1
C20: S2: Drag-and-Drop Scheduling | D20: 46132 | E20: 46143 | F20: Sprint 8 | G20: =IF(TODAY() > E20, 1, IF(TODAY() < D20, 0, (TODAY() - D20) / (E20 - D20))) -> 1 | H20: 1
C21: S3: Conflict Detection | D21: 46146 | E21: 46157 | F21: Sprint 9 | G21: =IF(TODAY() > E21, 1, IF(TODAY() < D21, 0, (TODAY() - D21) / (E21 - D21))) -> 1 | H21: 0.09
B22: Progress Tracking | D22: 46160 | E22: 46199
C23: S1: Daily Progress Dashboard | D23: 46160 | E23: 46171 | F23: Sprint 10 | G23: =IF(TODAY() > E23, 1, IF(TODAY() < D23, 0, (TODAY() - D23) / (E23 - D23))) -> 1 | H23: 0
C24: S2: Weekly Productivity Reports | D24: 46174 | E24: 46185 | F24: Sprint 11 | G24: =IF(TODAY() > E24, 1, IF(TODAY() < D24, 0, (TODAY() - D24) / (E24 - D24))) -> 1 | H24: 0
C25: S3: Streak/Gamification | D25: 46188 | E25: 46199 | F25: Sprint 12 | G25: =IF(TODAY() > E25, 1, IF(TODAY() < D25, 0, (TODAY() - D25) / (E25 - D25))) -> 1 | H25: 0

Sheet Master Plan V1
A1: Project Actual: | B1: =AVERAGE(H6, H14) -> 0.88625
A2: Project Plan: | B2: =AVERAGEIF(A6:A30, "MVP*", G6:G30) -> 1
A5: Module / Feature | B5: Task / Story ID | C5: Start | D5: End | E5: Sprint | F5: Health | G5: % Plan | H5: % Actual
A6: MVP1: ASM | C6: 46027 | D6: 46108 | E6: Ongoing | F6: Green | G6: =AVERAGE(G7, G11) -> 1 | H6: =AVERAGE(H8:H10, H12:H13,H16:H18) -> 0.88625
A7: CMMS | C7: 46027 | D7: 46052 | F7: Green | G7: =AVERAGE(G8:G10) -> 1
B8: S1: Login/Signup | C8: 46027 | D8: 46038 | E8: Sprint 1 | G8: =IF(TODAY() > D8, 1, IF(TODAY() < C8, 0, (TODAY() - C8) / (D8 - C8))) -> 1 | H8: 1
B9: S2: Home Page | C9: 46027 | D9: 46038 | E9: Sprint 1 | G9: =IF(TODAY() > D9, 1, IF(TODAY() < C9, 0, (TODAY() - C9) / (D9 - C9))) -> 1 | H9: 1
B10: S3: Profile Management | C10: 46041 | D10: 46052 | E10: Sprint 2 | G10: =IF(TODAY() > D10, 1, IF(TODAY() < C10, 0, (TODAY() - C10) / (D10 - C10))) -> 1 | H10: 1
A11: AI | C11: 46055 | D11: 46108 | F11: Green | G11: =AVERAGE(G12:G13) -> 1
B12: S1: Create/Edit Tasks | C12: 46055 | D12: 46066 | E12: Sprint 3 | G12: =IF(TODAY() > D12, 1, IF(TODAY() < C12, 0, (TODAY() - C12) / (D12 - C12))) -> 1 | H12: 1
B13: S2: Priority Labeling | C13: 46069 | D13: 46080 | E13: Sprint 4 | G13: =IF(TODAY() > D13, 1, IF(TODAY() < C13, 0, (TODAY() - C13) / (D13 - C13))) -> 1 | H13: 1
A14: MVP2: RCA | C14: 46118 | D14: 46199 | E14: Upcoming | F14: Green | G14: =AVERAGE(G15) -> 1
A15: Case creation - Create/Edit Analysis | C15: 46118 | D15: 46157 | F15: Green | G15: =AVERAGE(G16:G18) -> 1
B16: S1: Sync Google/Outlook | C16: 46118 | D16: 46129 | E16: Sprint 7 | G16: =IF(TODAY() > D16, 1, IF(TODAY() < C16, 0, (TODAY() - C16) / (D16 - C16))) -> 1 | H16: 1
B17: S2: Drag-and-Drop | C17: 46132 | D17: 46143 | E17: Sprint 8 | G17: =IF(TODAY() > D17, 1, IF(TODAY() < C17, 0, (TODAY() - C17) / (D17 - C17))) -> 1 | H17: 1
B18: S3: Conflict Detection | C18: 46146 | D18: 46157 | E18: Sprint 9 | G18: =IF(TODAY() > D18, 1, IF(TODAY() < C18, 0, (TODAY() - C18) / (D18 - C18))) -> 1 | H18: 0.09

Sheet Master Plan V2
A1: Project Actual: | B1: =AVERAGEIF(A6:A18, "MVP*", H6:H18) -> 0.84833333
A2: Project Plan: | B2: =AVERAGEIF(A6:A18, "MVP*", G6:G18) -> 1
A5: Module / Feature | B5: Task / Story ID | C5: Start | D5: End | E5: Sprint | F5: Health | G5: % Plan | H5: % Actual
A6: MVP1: ASM | C6: 46027 | D6: 46108 | E6: Ongoing | F6: Green | G6: =AVERAGE(G7, G11) -> 1 | H6: =AVERAGE(H7, H11) -> 1
A7: CMMS | C7: 46027 | D7: 46052 | F7: Green | G7: =AVERAGE(G8:G10) -> 1 | H7: =AVERAGE(H8:H10) -> 1
B8: S1: Login/Signup | C8: 46027 | D8: 46038 | E8: Sprint 1 | G8: =IF(TODAY() > D8, 1, IF(TODAY() < C8, 0, (TODAY() - C8) / (D8 - C8))) -> 1 | H8: 1
B9: S2: Home Page | C9: 46027 | D9: 46038 | E9: Sprint 1 | G9: =IF(TODAY() > D9, 1, IF(TODAY() < C9, 0, (TODAY() - C9) / (D9 - C9))) -> 1 | H9: 1
B10: S3: Profile Management | C10: 46041 | D10: 46052 | E10: Sprint 2 | G10: =IF(TODAY() > D10, 1, IF(TODAY() < C10, 0, (TODAY() - C10) / (D10 - C10))) -> 1 | H10: 1
A11: AI | C11: 46055 | D11: 46108 | F11: Green | G11: =AVERAGE(G12:G13) -> 1 | H11: =AVERAGE(H12:H13) -> 1
B12: S1: Create/Edit Tasks | C12: 46055 | D12: 46066 | E12: Sprint 3 | G12: =IF(TODAY() > D12, 1, IF(TODAY() < C12, 0, (TODAY() - C12) / (D12 - C12))) -> 1 | H12: 1
B13: S2: Priority Labeling | C13: 46069 | D13: 46080 | E13: Sprint 4 | G13: =IF(TODAY() > D13, 1, IF(TODAY() < C13, 0, (TODAY() - C13) / (D13 - C13))) -> 1 | H13: 1
A14: MVP2: RCA | C14: 46118 | D14: 46199 | E14: Upcoming | F14: Green | G14: =AVERAGE(G15) -> 1 | H14: =AVERAGE(H15) -> 0.69666667
A15: Case creation - Create/Edit Analysis | C15: 46118 | D15: 46157 | F15: Green | G15: =AVERAGE(G16:G18) -> 1 | H15: =AVERAGE(H16:H18) -> 0.69666667
B16: S1: Sync Google/Outlook | C16: 46118 | D16: 46129 | E16: Sprint 7 | G16: =IF(TODAY() > D16, 1, IF(TODAY() < C16, 0, (TODAY() - C16) / (D16 - C16))) -> 1 | H16: 1
B17: S2: Drag-and-Drop | C17: 46132 | D17: 46143 | E17: Sprint 8 | G17: =IF(TODAY() > D17, 1, IF(TODAY() < C17, 0, (TODAY() - C17) / (D17 - C17))) -> 1 | H17: 1
B18: S3: Conflict Detection | C18: 46146 | D18: 46157 | E18: Sprint 9 | G18: =IF(TODAY() > D18, 1, IF(TODAY() < C18, 0, (TODAY() - C18) / (D18 - C18))) -> 1 | H18: 0.09

Sheet master Plan V3
A1: Project Actual: | B1: =AVERAGEIF(A7:A19, "MVP*", H7:H19) -> 0.84833333 | D1: Project start | E1: 46027 | I1: Year 2026
A2: Project Plan: | B2: =AVERAGEIF(A7:A19, "MVP*", G7:G19) -> 1 | I2: Jan | M2: Feb | Q2: Mar | V2: Apr | Z2: May | AD2: Jun | AI2: Jul | AM2: Aug | AR2: Sep | AV2: Oct | AZ2: Nov | BE2: Dec
I3: 1 | J3: 1 | K3: 1 | L3: 1 | M3: 2 | N3: 2 | O3: 2 | P3: 2 | Q3: 3 | R3: 3 | S3: 3 | T3: 3 | U3: 3 | V3: 4 | W3: 4 | X3: 4 | Y3: 4 | Z3: 5 | AA3: 5 | AB3: 5 | AC3: 5 | AD3: 6 | AE3: 6 | AF3: 6 | AG3: 6 | AH3: 6 | AI3: 7 | AJ3: 7 | AK3: 7 | AL3: 7 | AM3: 8 | AN3: 8 | AO3: 8 | AP3: 8 | AQ3: 8 | AR3: 9 | AS3: 9 | AT3: 9 | AU3: 9 | AV3: 10 | AW3: 10 | AX3: 10 | AY3: 10 | AZ3: 11 | BA3: 11 | BB3: 11 | BC3: 11 | BD3: 11 | BE3: 12 | BF3: 12 | BG3: 12 | BH3: 12
I4: =DATE(2026, I$3, I6) -> 46027 | J4: =DATE(2026, J$3, J6) -> 46034 | K4: =DATE(2026, K$3, K6) -> 46041 | L4: =DATE(2026, L$3, L6) -> 46048 | M4: =DATE(2026, M$3, M6) -> 46055 | N4: =DATE(2026, N$3, N6) -> 46062 | O4: =DATE(2026, O$3, O6) -> 46069 | P4: =DATE(2026, P$3, P6) -> 46076 | ... BH4: =DATE(2026, BH$3, BH6) -> 46384
I5: sp18 | J5: sp19 | L5: sp20 | N5: sp21 | P5: sp22 | R5: sp23 | T5: sp24 | V5: sp25 | X5: sp26 | Z5: sp27 | AB5: sp28 | AD5: sp29 | AF5: sp30 | AH5: sp31 | AJ5: sp32 | AL5: sp33 | AN5: sp34 | AP5: sp35 | AR5: sp36 | AT5: sp37 | AV5: sp38 | AX5: sp39 | AZ5: sp40 | BB5: sp41 | BD5: sp42 | BF5: sp43
A6: Module / Feature | B6: Task / Story ID | C6: Start | D6: End | E6: Sprint | F6: Health | G6: % Plan | H6: % Actual | I6: 5 | J6: 12 | K6: 19 | L6: 26 | M6: 2 | N6: 9 | O6: 16 | P6: 23 | Q6: 2 | R6: 9 | S6: 16 | T6: 23 | U6: 30 | V6: 6 | W6: 13 | X6: 20 | Y6: 27 | Z6: 4 | AA6: 11 | AB6: 18 | AC6: 25 | AD6: 1 | AE6: 8 | AF6: 15 | AG6: 22 | AH6: 29 | AI6: 6 | AJ6: 13 | AK6: 20 | AL6: 27 | AM6: 3 | AN6: 10 | AO6: 17 | AP6: 24 | AQ6: 31 | AR6: 7 | AS6: 14 | AT6: 21 | AU6: 28 | AV6: 5 | AW6: 12 | AX6: 19 | AY6: 26 | AZ6: 2 | BA6: 9 | BB6: 16 | BC6: 23 | BD6: 30 | BE6: 7 | BF6: 14 | BG6: 21 | BH6: 28
A7: MVP1: ASM | C7: 46027 | D7: 46108 | F7: Green | G7: =AVERAGE(G8, G12) -> 1 | H7: =AVERAGE(H8, H12) -> 1
A8: CMMS | C8: 46027 | D8: 46052 | F8: Green | G8: =AVERAGE(G9:G11) -> 1 | H8: =AVERAGE(H9:H11) -> 1
B9: S1: Login/Signup | C9: 46027 | D9: 46039 | E9: Sprint 1 | G9: =IF(TODAY() > D9, 1, IF(TODAY() < C9, 0, (TODAY() - C9) / (D9 - C9))) -> 1 | H9: 1
B10: S2: Home Page | C10: 46027 | D10: 46038 | E10: Sprint 1 | G10: =IF(TODAY() > D10, 1, IF(TODAY() < C10, 0, (TODAY() - C10) / (D10 - C10))) -> 1 | H10: 1
B11: S3: Profile Management | C11: 46041 | D11: 46052 | E11: Sprint 2 | G11: =IF(TODAY() > D11, 1, IF(TODAY() < C11, 0, (TODAY() - C11) / (D11 - C11))) -> 1 | H11: 1
A12: AI | C12: 46055 | D12: 46108 | F12: Green | G12: =AVERAGE(G13:G14) -> 1 | H12: =AVERAGE(H13:H14) -> 1
B13: S1: Create/Edit Tasks | C13: 46055 | D13: 46066 | E13: Sprint 3 | G13: =IF(TODAY() > D13, 1, IF(TODAY() < C13, 0, (TODAY() - C13) / (D13 - C13))) -> 1 | H13: 1
B14: S2: Priority Labeling | C14: 46069 | D14: 46080 | E14: Sprint 4 | G14: =IF(TODAY() > D14, 1, IF(TODAY() < C14, 0, (TODAY() - C14) / (D14 - C14))) -> 1 | H14: 1
A15: MVP2: RCA | C15: 46118 | D15: 46199 | F15: Green | G15: =AVERAGE(G16) -> 1 | H15: =AVERAGE(H16) -> 0.69666667
A16: Case creation - Create/Edit Analysis | C16: 46118 | D16: 46157 | F16: Green | G16: =AVERAGE(G17:G19) -> 1 | H16: =AVERAGE(H17:H19) -> 0.69666667
B17: S1: Sync Google/Outlook | C17: 46118 | D17: 46129 | E17: Sprint 7 | G17: =IF(TODAY() > D17, 1, IF(TODAY() < C17, 0, (TODAY() - C17) / (D17 - C17))) -> 1 | H17: 1
B18: S2: Drag-and-Drop | C18: 46132 | D18: 46143 | E18: Sprint 8 | G18: =IF(TODAY() > D18, 1, IF(TODAY() < C18, 0, (TODAY() - C18) / (D18 - C18))) -> 1 | H18: 1
B19: S3: Conflict Detection | C19: 46146 | D19: 46157 | E19: Sprint 9 | G19: =IF(TODAY() > D19, 1, IF(TODAY() < C19, 0, (TODAY() - C19) / (D19 - C19))) -> 1 | H19: 0.09

Sheet master plan V4
A1: Project Actual: | B1: =AVERAGEIF(A7:A19, "MVP*", H7:H19) -> 0.85 | D1: Project start | E1: 46027 | I1: Year 2026
A2: Project Plan: | B2: =AVERAGEIF(A7:A19, "MVP*", G7:G19) -> 1 | I2: Jan | M2: Feb | Q2: Mar | V2: Apr | Z2: May | AD2: Jun | AI2: Jul | AM2: Aug | AR2: Sep | AV2: Oct | AZ2: Nov | BE2: Dec
I3: 1 | J3: 1 | K3: 1 | L3: 1 | M3: 2 | N3: 2 | O3: 2 | P3: 2 | Q3: 3 | R3: 3 | S3: 3 | T3: 3 | U3: 3 | V3: 4 | W3: 4 | X3: 4 | Y3: 4 | Z3: 5 | AA3: 5 | AB3: 5 | AC3: 5 | AD3: 6 | AE3: 6 | AF3: 6 | AG3: 6 | AH3: 6 | AI3: 7 | AJ3: 7 | AK3: 7 | AL3: 7 | AM3: 8 | AN3: 8 | AO3: 8 | AP3: 8 | AQ3: 8 | AR3: 9 | AS3: 9 | AT3: 9 | AU3: 9 | AV3: 10 | AW3: 10 | AX3: 10 | AY3: 10 | AZ3: 11 | BA3: 11 | BB3: 11 | BC3: 11 | BD3: 11 | BE3: 12 | BF3: 12 | BG3: 12 | BH3: 12
I4: =DATE(2026, I$3, I6) -> 46027 | J4: =DATE(2026, J$3, J6) -> 46034 | K4: =DATE(2026, K$3, K6) -> 46041 | L4: =DATE(2026, L$3, L6) -> 46048 | M4: =DATE(2026, M$3, M6) -> 46055 | N4: =DATE(2026, N$3, N6) -> 46062 | O4: =DATE(2026, O$3, O6) -> 46069 | P4: =DATE(2026, P$3, P6) -> 46076 | ... BH4: =DATE(2026, BH$3, BH6) -> 46384
I5: sp18 | J5: sp19 | L5: sp20 | N5: sp21 | P5: sp22 | R5: sp23 | T5: sp24 | V5: sp25 | X5: sp26 | Z5: sp27 | AB5: sp28 | AD5: sp29 | AF5: sp30 | AH5: sp31 | AJ5: sp32 | AL5: sp33 | AN5: sp34 | AP5: sp35 | AR5: sp36 | AT5: sp37 | AV5: sp38 | AX5: sp39 | AZ5: sp40 | BB5: sp41 | BD5: sp42 | BF5: sp43
A6: Module / Feature | B6: Task / Story ID | C6: Start | D6: End | E6: Sprint | F6: Health | G6: % Plan | H6: % Actual | I6: 5 | J6: 12 | K6: 19 | L6: 26 | M6: 2 | N6: 9 | O6: 16 | P6: 23 | Q6: 2 | R6: 9 | S6: 16 | T6: 23 | U6: 30 | V6: 6 | W6: 13 | X6: 20 | Y6: 27 | Z6: 4 | AA6: 11 | AB6: 18 | AC6: 25 | AD6: 1 | AE6: 8 | AF6: 15 | AG6: 22 | AH6: 29 | AI6: 6 | AJ6: 13 | AK6: 20 | AL6: 27 | AM6: 3 | AN6: 10 | AO6: 17 | AP6: 24 | AQ6: 31 | AR6: 7 | AS6: 14 | AT6: 21 | AU6: 28 | AV6: 5 | AW6: 12 | AX6: 19 | AY6: 26 | AZ6: 2 | BA6: 9 | BB6: 16 | BC6: 23 | BD6: 30 | BE6: 7 | BF6: 14 | BG6: 21 | BH6: 28
A7: MVP1: ASM | C7: 46027 | D7: 46108 | F7: Category | G7: =AVERAGE(G8, G12) -> 1 | H7: =AVERAGE(H8, H12) -> 1
A8: CMMS | C8: 46027 | D8: 46052 | G8: =AVERAGE(G9:G11) -> 1 | H8: =AVERAGE(H9:H11) -> 1
B9: S1: Login/Signup | C9: 46027 | D9: 46039 | E9: Sprint 1 | G9: =IF(TODAY() > D9, 1, IF(TODAY() < C9, 0, (TODAY() - C9) / (D9 - C9))) -> 1 | H9: 1
B10: S2: Home Page | C10: 46027 | D10: 46038 | E10: Sprint 1 | G10: =IF(TODAY() > D10, 1, IF(TODAY() < C10, 0, (TODAY() - C10) / (D10 - C10))) -> 1 | H10: 1
B11: S3: Profile Management | C11: 46041 | D11: 46052 | E11: Sprint 2 | G11: =IF(TODAY() > D11, 1, IF(TODAY() < C11, 0, (TODAY() - C11) / (D11 - C11))) -> 1 | H11: 1
A12: AI | C12: 46055 | D12: 46108 | G12: =AVERAGE(G13:G14) -> 1 | H12: =AVERAGE(H13:H14) -> 1
B13: S1: Create/Edit Tasks | C13: 46055 | D13: 46066 | E13: Sprint 3 | G13: =IF(TODAY() > D13, 1, IF(TODAY() < C13, 0, (TODAY() - C13) / (D13 - C13))) -> 1 | H13: 1
B14: S2: Priority Labeling | C14: 46069 | D14: 46080 | E14: Sprint 4 | G14: =IF(TODAY() > D14, 1, IF(TODAY() < C14, 0, (TODAY() - C14) / (D14 - C14))) -> 1 | H14: 1
A15: MVP2: RCA | C15: 46118 | D15: 46199 | G15: =AVERAGE(G16) -> 1 | H15: =AVERAGE(H16) -> 0.7
A16: Case creation - Create/Edit Analysis | C16: 46118 | D16: 46157 | G16: =AVERAGE(G17:G19) -> 1 | H16: =AVERAGE(H17:H19) -> 0.7
B17: [Improvement][ASM][AssetStrategy] Table List - Searching and Sorting field Unmitigated Matrix, Mitigated Matrix | C17: 46118 | D17: 46129 | E17: Sprint 7 | G17: =IF(TODAY() > D17, 1, IF(TODAY() < C17, 0, (TODAY() - C17) / (D17 - C17))) -> 1 | H17: 1
B18: [ASM][AssetStrategy][Revisions] Revision Details - Strategy Summary - Tab Summary | C18: 46132 | D18: 46143 | E18: Sprint 8 | G18: =IF(TODAY() > D18, 1, IF(TODAY() < C18, 0, (TODAY() - C18) / (D18 - C18))) -> 1 | H18: 1
B19: [ASM][AssetStrategy][Revisions] Revision Details - Strategy Summary - Tab Details | C19: 46146 | D19: 46157 | E19: Sprint 9 | G19: =IF(TODAY() > D19, 1, IF(TODAY() < C19, 0, (TODAY() - C19) / (D19 - C19))) -> 1 | H19: 0.1
A20: Additional Requirement | C20: 46118 | D20: 46157
B21: [Improvement][ASM][AssetStrategy] Table List - Searching and Sorting field Unmitigated Matrix, Mitigated Matrix | C21: 46132 | D21: 46143 | E21: Sprint 1 | G21: =IF(TODAY() > D21, 1, IF(TODAY() < C21, 0, (TODAY() - C21) / (D21 - C21))) -> 1 | H21: 1
B22: [ASM][AssetStrategy][Revisions] Revision Details - Strategy Summary - Tab Summary | C22: 46146 | D22: 46157 | E22: Sprint 1 | G22: =IF(TODAY() > D22, 1, IF(TODAY() < C22, 0, (TODAY() - C22) / (D22 - C22))) -> 1 | H22: 1
B23: [ASM][AssetStrategy][Revisions] Revision Details - Strategy Summary - Tab Details | C23: 46132 | D23: 46143 | E23: Sprint 2 | G23: =IF(TODAY() > D23, 1, IF(TODAY() < C23, 0, (TODAY() - C23) / (D23 - C23))) -> 1 | H23: 0
B24: [ASM][AssetStrategy][Revisions] Revision Details - Strategy Summary - Tab Details | C24: 46176 | D24: 46203 | E24: Sprint 9 | G24: =IF(TODAY() > D24, 1, IF(TODAY() < C24, 0, (TODAY() - C24) / (D24 - C24))) -> 1 | H24: 0.1

Sheet master plan V5
A1: Project Plan: | B1: =AVERAGE(G8:G14) -> 1 | C1: Project start: | D1: 46027
A2: Project Actual: | B2: =AVERAGE(H8,H9,H12,H13,H14) -> 0.93333333 | C2: Project end: | D2: 46157 | J2: Year 2026
J3: Jan | N3: Feb | R3: Mar | W3: Apr | AA3: May | AE3: Jun | AJ3: Jul | AN3: Aug | AS3: Sep | AW3: Oct | BA3: Nov | BF3: Dec
J4: 5 | K4: 12 | L4: 19 | M4: 26 | N4: 2 | O4: 9 | P4: 16 | Q4: 23 | R4: 2 | S4: 9 | T4: 16 | U4: 23 | V4: 30 | W4: 6 | X4: 13 | Y4: 20 | Z4: 27 | AA4: 4 | AB4: 11 | AC4: 18 | AD4: 25 | AE4: 1 | AF4: 8 | AG4: 15 | AH4: 22 | AI4: 29 | AJ4: 6 | AK4: 13 | AL4: 20 | AM4: 27 | AN4: 3 | AO4: 10 | AP4: 17 | AQ4: 24 | AR4: 31 | AS4: 7 | AT4: 14 | AU4: 21 | AV4: 28 | AW4: 5 | AX4: 12 | AY4: 19 | AZ4: 26 | BA4: 2 | BB4: 9 | BC4: 16 | BD4: 23 | BE4: 30 | BF4: 7 | BG4: 14 | BH4: 21 | BI4: 28
J5: W1 | K5: W2 | L5: W3 | M5: W4 | N5: W5 | O5: W6 | P5: W7 | Q5: W8 | R5: W9 | S5: W10 | T5: W11 | U5: W12 | V5: W13 | W5: W14 | X5: W15 | Y5: W16 | Z5: W17 | AA5: W18 | AB5: W19 | AC5: W20 | AD5: W21 | AE5: W22 | AF5: W23 | AG5: W24 | AH5: W25 | AI5: W26 | AJ5: W27 | AK5: W28 | AL5: W29 | AM5: W30 | AN5: W31 | AO5: W32 | AP5: W33 | AQ5: W34 | AR5: W35 | AS5: W36 | AT5: W37 | AU5: W38 | AV5: W39 | AW5: W40 | AX5: W41 | AY5: W42 | AZ5: W43 | BA5: W44 | BB5: W45 | BC5: W46 | BD5: W47 | BE5: W48 | BF5: W49 | BG5: W50 | BH5: W51 | BI5: W52
A6: Module | B6: Feature | C6: Start | D6: End | E6: Sprint | F6: Working Day | G6: % Plan | H6: % Actual | I6: status | J6: sp18 | K6: sp19 | M6: sp20 | O6: sp21 | Q6: sp22 | S6: sp23 | U6: sp24 | W6: sp25 | Y6: sp26 | AA6: sp27 | AC6: sp28 | AE6: sp29 | AG6: sp30 | AI6: sp31 | AK6: sp32 | AM6: sp33 | AO6: sp34 | AQ6: sp35 | AS6: sp36 | AU6: sp37 | AW6: sp38 | AY6: sp39 | BA6: sp40 | BC6: sp41 | BE6: sp42 | BG6: sp43 | BI6: sp44
A7: MVP1: ASM
B8: feature a | C8: 46027 | D8: 46045 | E8: 18-19 | F8: =NETWORKDAYS(C8, D8, holiday!$A$2:$A$18) -> 15 | G8: =MIN(1, MAX(0, NETWORKDAYS(C8, TODAY(), holiday!$A$2:$A$18) / F8)) -> 1 | H8: =COUNTIFS('Requirement Baseline v5'!B:B,B8,'Requirement Baseline v5'!E:E,1)/COUNTIF('Requirement Baseline v5'!B:B,'master plan V5'!B8) -> 1 | I8: completed
B9: feature b | C9: 46048 | D9: 46073 | E9: 20-21 | F9: =NETWORKDAYS(C9, D9, holiday!$A$2:$A$18) -> 20 | G9: =MIN(1, MAX(0, NETWORKDAYS(C9, TODAY(), holiday!$A$2:$A$18) / F9)) -> 1 | H9: =COUNTIFS('Requirement Baseline v5'!B:B,B9,'Requirement Baseline v5'!E:E,1)/COUNTIF('Requirement Baseline v5'!B:B,'master plan V5'!B9) -> 1 | I9: completed
B10: feature c | C10: 46048 | D10: 46073 | E10: 20-21 | F10: =NETWORKDAYS(C10, D10, holiday!$A$2:$A$18) -> 20 | G10: =MIN(1, MAX(0, NETWORKDAYS(C10, TODAY(), holiday!$A$2:$A$18) / F10)) -> 1 | H10: =COUNTIFS('Requirement Baseline v5'!B:B,B10,'Requirement Baseline v5'!E:E,1)/COUNTIF('Requirement Baseline v5'!B:B,'master plan V5'!B10) -> 1 | I10: completed
A11: MVP2: RCA
B12: feature d | C12: 46062 | D12: 46101 | E12: 21-23 | F12: =NETWORKDAYS(C12, D12, holiday!$A$2:$A$18) -> 29 | G12: =MIN(1, MAX(0, NETWORKDAYS(C12, TODAY(), holiday!$A$2:$A$18) / F12)) -> 1 | H12: =COUNTIFS('Requirement Baseline v5'!B:B,B12,'Requirement Baseline v5'!E:E,1)/COUNTIF('Requirement Baseline v5'!B:B,'master plan V5'!B12) -> 1 | I12: completed
B13: feature d | C13: 46104 | D13: 46129 | E13: 23-25 | F13: =NETWORKDAYS(C13, D13, holiday!$A$2:$A$18) -> 16 | G13: =MIN(1, MAX(0, NETWORKDAYS(C13, TODAY(), holiday!$A$2:$A$18) / F13)) -> 1 | H13: =COUNTIFS('Requirement Baseline v5'!B:B,B13,'Requirement Baseline v5'!E:E,1)/COUNTIF('Requirement Baseline v5'!B:B,'master plan V5'!B13) -> 1 | I13: completed
B14: feature e | C14: 46132 | D14: 46157 | E14: 25-26 | F14: =NETWORKDAYS(C14, D14, holiday!$A$2:$A$18) -> 18 | G14: =MIN(1, MAX(0, NETWORKDAYS(C14, TODAY(), holiday!$A$2:$A$18) / F14)) -> 1 | H14: =COUNTIFS('Requirement Baseline v5'!B:B,B14,'Requirement Baseline v5'!E:E,1)/COUNTIF('Requirement Baseline v5'!B:B,'master plan V5'!B14) -> 0.66666667 | I14: in progress

Sheet Requirement Baseline v5
A1: Module | B1: Feature Name | C1: User Story ID | D1: Sprint | E1: Status (1=Done, 0=Progress)
A2: ASM | B2: feature A | C2: us1 | D2: 18 | E2: 1
A3: ASM | B3: feature A | C3: us2 | D3: 18 | E3: 1
A4: ASM | B4: feature A | C4: us3 | D4: 19 | E4: 1
A5: ASM | B5: feature B | C5: us1 | D5: 20 | E5: 1
A6: ASM | B6: feature B | C6: us2 | D6: 21 | E6: 1
A7: ASM | B7: feature B | C7: us3 | D7: 21 | E7: 1
A8: RCA | B8: feature C | C8: us1 | D8: 21 | E8: 1
A9: RCA | B9: feature C | C9: us2 | D9: 22 | E9: 1
A10: RCA | B10: feature C | C10: us3 | D10: 23 | E10: 1
A11: RCA | B11: feature D | C11: us1 | D11: 23 | E11: 1
A12: RCA | B12: feature D | C12: us2 | D12: 24 | E12: 1
A13: RCA | B13: feature D | C13: us3 | D13: 25 | E13: 1
... A16: RCA | B16: feature E | C16: us3 | D16: 26 | E16: 0

Sheet master plan v6
A1: Project Plan: | B1: =AVERAGE(H8, H12, H19, H22) -> 0.44276316 | C1: Project start: | D1: 46027
A2: Project Actual: | B2: =AVERAGE(I8, I12, I19, I22) -> 0.375 | C2: Project end: | D2: =MAX(C8:D24) -> 46381 | K2: Year 2026
C3: Baseline: | D3: =D2 -> 46381 | K3: Jan | O3: Feb | S3: Mar | X3: Apr | AB3: May | AF3: Jun | AK3: Jul | AO3: Aug | AT3: Sep | AX3: Oct | BB3: Nov | BG3: Dec
K4: =D1 -> 46027 | L4: =K4+7 -> 46034 | M4: =L4+7 -> 46041 | N4: =M4+7 -> 46048 | O4: =N4+7 -> 46055 | P4: =O4+7 -> 46062 | Q4: =P4+7 -> 46069 | R4: =Q4+7 -> 46076 | S4: =R4+7 -> 46083 | ... BJ4: =BI4+7 -> 46384
K5: W1 | L5: W2 | M5: W3 | N5: W4 | O5: W5 | P5: W6 | Q5: W7 | R5: W8 | S5: W9 | T5: W10 | U5: W11 | V5: W12 | W5: W13 | X5: W14 | Y5: W15 | Z5: W16 | AA5: W17 | AB5: W18 | AC5: W19 | AD5: W20 | AE5: W21 | AF5: W22 | AG5: W23 | AH5: W24 | AI5: W25 | AJ5: W26 | AK5: W27 | AL5: W28 | AM5: W29 | AN5: W30 | AO5: W31 | AP5: W32 | AQ5: W33 | AR5: W34 | AS5: W35 | AT5: W36 | AU5: W37 | AV5: W38 | AW5: W39 | AX5: W40 | AY5: W41 | AZ5: W42 | BA5: W43 | BB5: W44 | BC5: W45 | BD5: W46 | BE5: W47 | BF5: W48 | BG5: W49 | BH5: W50 | BI5: W51 | BJ5: W52
K6: sp18 | L6: sp19 | N6: sp20 | P6: sp21 | R6: sp22 | T6: sp23 | V6: sp24 | X6: sp25 | Z6: sp26 | AB6: sp27 | AD6: sp28 | AF6: sp29 | AH6: sp30 | AJ6: sp31 | AL6: sp32 | AN6: sp33 | AP6: sp34 | AR6: sp35 | AT6: sp36 | AV6: sp37 | AX6: sp38 | AZ6: sp39 | BB6: sp40 | BD6: sp41 | BF6: sp42 | BH6: sp43 | BJ6: sp44
A7: Module | B7: Feature | C7: Start | D7: End | E7: Sprint | F7: % Weight | G7: Working Day | H7: % Plan | I7: % Actual | J7: status
A8: MVP1: ASM+AI | C8: =MIN(C9:D11) -> 46027 | D8: =MAX(C9:D11) -> 46157 | G8: =SUM(G9:G11) -> 97 | H8: =AVERAGE(H9:H11) -> 1 | I8: =AVERAGE(I9:I11) -> 1
B9: Revision | C9: 46027 | D9: 46045 | E9: 18-19 | F9: 0.75 | G9: =NETWORKDAYS(C9, D9, holiday!$A$2:$A$18) -> 15 | H9: =MIN(1, MAX(0, NETWORKDAYS(C9, TODAY(), holiday!$A$2:$A$18) / G9)) -> 1 | I9: =COUNTIFS('baseline v4'!B:B,B9,'baseline v4'!H:H,1)/COUNTIF('baseline v4'!B:B,'master plan v6'!B9) -> 1 | J9: {=_xlfn.IFS(AND(H9=1, I9=1), "completed", AND(H9=0, I9=0), "not start yet", TRUE, "in progress")} -> completed
B10: CMMS | C10: 46048 | D10: 46157 | E10: 20-27 | F10: 0.91 | G10: =NETWORKDAYS(C10, D10, holiday!$A$2:$A$18) -> 73 | H10: =MIN(1, MAX(0, NETWORKDAYS(C10, TODAY(), holiday!$A$2:$A$18) / G10)) -> 1 | I10: =COUNTIFS('baseline v4'!B:B,B10,'baseline v4'!H:H,1)/COUNTIF('baseline v4'!B:B,'master plan v6'!B10) -> 1 | J10: {=_xlfn.IFS(AND(H10=1, I10=1), "completed", AND(H10=0, I10=0), "not start yet", TRUE, "in progress")} -> completed
B11: AI | C11: 46076 | D11: 46087 | E11: 22 | F11: 0.9 | G11: =NETWORKDAYS(C11, D11, holiday!$A$2:$A$18) -> 9 | H11: =MIN(1, MAX(0, NETWORKDAYS(C11, TODAY(), holiday!$A$2:$A$18) / G11)) -> 1 | I11: =COUNTIFS('baseline v4'!B:B,B11,'baseline v4'!H:H,1)/COUNTIF('baseline v4'!B:B,'master plan v6'!B11) -> 1 | J11: {=_xlfn.IFS(AND(H11=1, I11=1), "completed", AND(H11=0, I11=0), "not start yet", TRUE, "in progress")} -> completed
A12: MVP2: RCA | C12: =MIN(C13:D18) -> 46146 | D12: =MAX(C13:D18) -> 46269 | G12: =SUM(G13:G18) -> 131 | H12: =AVERAGE(H13:H18) -> 0.77105263 | I12: =AVERAGEA(I13:I18) -> 0.5
B13: Case Creation - Create/Edit Analysis | C13: 46146 | D13: 46213 | E13: 27-31 | F13: 0.94 | G13: =NETWORKDAYS(C13, D13, holiday!$A$2:$A$18) -> 47 | H13: =MIN(1, MAX(0, NETWORKDAYS(C13, TODAY(), holiday!$A$2:$A$18) / G13)) -> 1 | I13: =COUNTIFS('baseline v4'!B:B,B13,'baseline v4'!H:H,1)/COUNTIF('baseline v4'!B:B,'master plan v6'!B13) -> 1 | J13: {=_xlfn.IFS(AND(H13=1, I13=1), "completed", AND(H13=0, I13=0), "not start yet", TRUE, "in progress")} -> completed
B14: Case Approval | C14: 46202 | D14: 46227 | E14: 31-32 | F14: 1 | G14: =NETWORKDAYS(C14, D14, holiday!$A$2:$A$18) -> 20 | H14: =MIN(1, MAX(0, NETWORKDAYS(C14, TODAY(), holiday!$A$2:$A$18) / G14)) -> 1 | I14: =COUNTIFS('baseline v4'!B:B,B14,'baseline v4'!H:H,1)/COUNTIF('baseline v4'!B:B,'master plan v6'!B14) -> 1 | J14: {=_xlfn.IFS(AND(H14=1, I14=1), "completed", AND(H14=0, I14=0), "not start yet", TRUE, "in progress")} -> completed
B15: Report | C15: 46216 | D15: 46241 | E15: 32-33 | F15: 0.9 | G15: =NETWORKDAYS(C15, D15, holiday!$A$2:$A$18) -> 18 | H15: =MIN(1, MAX(0, NETWORKDAYS(C15, TODAY(), holiday!$A$2:$A$18) / G15)) -> 1 | I15: =COUNTIFS('baseline v4'!B:B,B15,'baseline v4'!H:H,1)/COUNTIF('baseline v4'!B:B,'master plan v6'!B15) -> 1 | J15: {=_xlfn.IFS(AND(H15=1, I15=1), "completed", AND(H15=0, I15=0), "not start yet", TRUE, "in progress")} -> completed
B16: RCA Dashboard. | C16: 46230 | D16: 46255 | E16: 33-34 | F16: 0.85 | G16: =NETWORKDAYS(C16, D16, holiday!$A$2:$A$18) -> 17 | H16: =MIN(1, MAX(0, NETWORKDAYS(C16, TODAY(), holiday!$A$2:$A$18) / G16)) -> 1 | I16: =COUNTIFS('baseline v4'!B:B,B16,'baseline v4'!H:H,1)/COUNTIF('baseline v4'!B:B,'master plan v6'!B16) -> 0 | J16: {=_xlfn.IFS(AND(H16=1, I16=1), "completed", AND(H16=0, I16=0), "not start yet", TRUE, "in progress")} -> in progress
B17: User Management | C17: 46244 | D17: 46269 | E17: 34-35 | F17: 0.95 | G17: =NETWORKDAYS(C17, D17, holiday!$A$2:$A$18) -> 19 | H17: =MIN(1, MAX(0, NETWORKDAYS(C17, TODAY(), holiday!$A$2:$A$18) / G17)) -> 0.52631579 | I17: =COUNTIFS('baseline v4'!B:B,B17,'baseline v4'!H:H,1)/COUNTIF('baseline v4'!B:B,'master plan v6'!B17) -> 0 | J17: {=_xlfn.IFS(AND(H17=1, I17=1), "completed", AND(H17=0, I17=0), "not start yet", TRUE, "in progress")} -> in progress
B18: Noti Email | C18: 46258 | D18: 46269 | E18: 35 | F18: 1 | G18: =NETWORKDAYS(C18, D18, holiday!$A$2:$A$18) -> 10 | H18: =MIN(1, MAX(0, NETWORKDAYS(C18, TODAY(), holiday!$A$2:$A$18) / G18)) -> 0.1 | I18: =COUNTIFS('baseline v4'!B:B,B18,'baseline v4'!H:H,1)/COUNTIF('baseline v4'!B:B,'master plan v6'!B18) -> 0 | J18: {=_xlfn.IFS(AND(H18=1, I18=1), "completed", AND(H18=0, I18=0), "not start yet", TRUE, "in progress")} -> in progress
A19: UI Improvement | C19: =MIN(C20:D21) -> 46272 | D19: =MAX(C20:D21) -> 46353 | G19: =SUM(G20:G21) -> 58 | H19: =AVERAGE(H20:H21) -> 0 | I19: =AVERAGEA(I20:I21) -> 0
B20: Requirement & Design | C20: 46272 | D20: 46297 | E20: 36-37 | F20: 1 | G20: =NETWORKDAYS(C20, D20, holiday!$A$2:$A$18) -> 20 | H20: =MIN(1, MAX(0, NETWORKDAYS(C20, TODAY(), holiday!$A$2:$A$18) / G20)) -> 0 | I20: =COUNTIFS('baseline v4'!B:B,B20,'baseline v4'!H:H,1)/COUNTIF('baseline v4'!B:B,'master plan v6'!B20) -> 0 | J20: {=_xlfn.IFS(AND(H20=1, I20=1), "completed", AND(H20=0, I20=0), "not start yet", TRUE, "in progress")} -> not start yet
B21: Implementation, Testing, and Deploy | C21: 46300 | D21: 46353 | E21: 38-41 | F21: 1 | G21: =NETWORKDAYS(C21, D21, holiday!$A$2:$A$18) -> 38 | H21: =MIN(1, MAX(0, NETWORKDAYS(C21, TODAY(), holiday!$A$2:$A$18) / G21)) -> 0 | I21: =COUNTIFS('baseline v4'!B:B,B21,'baseline v4'!H:H,1)/COUNTIF('baseline v4'!B:B,'master plan v6'!B21) -> 0 | J21: {=_xlfn.IFS(AND(H21=1, I21=1), "completed", AND(H21=0, I21=0), "not start yet", TRUE, "in progress")} -> not start yet
A22: Handover | C22: =MIN(C23:D24) -> 46356 | D22: =MAX(C23:D26) -> 46381 | G22: =SUM(G23:G24) -> 19 | H22: =AVERAGE(H23:H24) -> 0 | I22: =AVERAGEA(I23:I24) -> 0
B23: Document | C23: 46356 | D23: 46367 | E23: 42 | F23: 1 | G23: =NETWORKDAYS(C23, D23, holiday!$A$2:$A$18) -> 9 | H23: =MIN(1, MAX(0, NETWORKDAYS(C23, TODAY(), holiday!$A$2:$A$18) / G23)) -> 0 | I23: =COUNTIFS('baseline v4'!B:B,B23,'baseline v4'!H:H,1)/COUNTIF('baseline v4'!B:B,'master plan v6'!B23) -> 0 | J23: {=_xlfn.IFS(AND(H23=1, I23=1), "completed", AND(H23=0, I23=0), "not start yet", TRUE, "in progress")} -> not start yet
B24: Knowledge Transfer | C24: 46370 | D24: 46381 | E24: 43 | F24: 1 | G24: =NETWORKDAYS(C24, D24, holiday!$A$2:$A$18) -> 10 | H24: =MIN(1, MAX(0, NETWORKDAYS(C24, TODAY(), holiday!$A$2:$A$18) / G24)) -> 0 | I24: =COUNTIFS('baseline v4'!B:B,B24,'baseline v4'!H:H,1)/COUNTIF('baseline v4'!B:B,'master plan v6'!B24) -> 0 | J24: {=_xlfn.IFS(AND(H24=1, I24=1), "completed", AND(H24=0, I24=0), "not start yet", TRUE, "in progress")} -> not start yet
A27: Assumption:
A28: 1) the project plan based on the requirement baseline sheet "baseline"
A29: 2) additional improvement and scope can be discussed in terms of trade-off OR additional requirement
A30: 3) the actual % is weighted by working days, excluding holidays

Sheet master plan bk1
A1: Project Plan: | B1: =AVERAGE(H:H) -> 0.85430622 | C1: Project start: | D1: 46027 | F1: Baseline | G1: =D2 -> 46269
A2: Project Actual: | B2: =AVERAGE(I:I) -> 0.68181818 | C2: Project end: | D2: =MAX(C8:D18) -> 46269 | K2: Year 2026
C3: total user story: | D3: ='baseline v4'!N47+'baseline v4'!N49 -> 0 | K3: Jan | O3: Feb | S3: Mar | X3: Apr | AB3: May | AF3: Jun | AK3: Jul | AO3: Aug | AT3: Sep | AX3: Oct | BB3: Nov | BG3: Dec
K4: =D1 -> 46027 | L4: =K4+7 -> 46034 | M4: =L4+7 -> 46041 | N4: =M4+7 -> 46048 | O4: =N4+7 -> 46055 | P4: =O4+7 -> 46062 | Q4: =P4+7 -> 46069 | R4: =Q4+7 -> 46076 | S4: =R4+7 -> 46083 | ... BJ4: =BI4+7 -> 46384
K5: W1 | L5: W2 | M5: W3 | N5: W4 | O5: W5 | P5: W6 | Q5: W7 | R5: W8 | S5: W9 | T5: W10 | U5: W11 | V5: W12 | W5: W13 | X5: W14 | Y5: W15 | Z5: W16 | AA5: W17 | AB5: W18 | AC5: W19 | AD5: W20 | AE5: W21 | AF5: W22 | AG5: W23 | AH5: W24 | AI5: W25 | AJ5: W26 | AK5: W27 | AL5: W28 | AM5: W29 | AN5: W30 | AO5: W31 | AP5: W32 | AQ5: W33 | AR5: W34 | AS5: W35 | AT5: W36 | AU5: W37 | AV5: W38 | AW5: W39 | AX5: W40 | AY5: W41 | AZ5: W42 | BA5: W43 | BB5: W44 | BC5: W45 | BD5: W46 | BE5: W47 | BF5: W48 | BG5: W49 | BH5: W50 | BI5: W51 | BJ5: W52
K6: sp18 | L6: sp19 | N6: sp20 | P6: sp21 | R6: sp22 | T6: sp23 | V6: sp24 | X6: sp25 | Z6: sp26 | AB6: sp27 | AD6: sp28 | AF6: sp29 | AH6: sp30 | AJ6: sp31 | AL6: sp32 | AN6: sp33 | AP6: sp34 | AR6: sp35 | AT6: sp36 | AV6: sp37 | AX6: sp38 | AZ6: sp39 | BB6: sp40 | BD6: sp41 | BF6: sp42 | BH6: sp43 | BJ6: sp44
A7: Module | B7: Feature | C7: Start | D7: End | E7: Sprint | F7: % Weight | G7: Working Day | H7: % Plan | I7: % Actual | J7: status
A8: MVP1: ASM+AI | C8: =MIN(C9:D11) -> 46027 | D8: =MAX(C9:D11) -> 46157 | H8: =AVERAGE(H9:H11) -> 1 | I8: =AVERAGE(I9:I11) -> 1
B9: Revision | C9: 46027 | D9: 46045 | E9: 18-19 | F9: 0.75 | G9: =NETWORKDAYS(C9, D9, holiday!$A$2:$A$18) -> 15 | H9: =MIN(1, MAX(0, NETWORKDAYS(C9, TODAY(), holiday!$A$2:$A$18) / G9)) -> 1 | I9: =COUNTIFS('baseline v4'!B:B,B9,'baseline v4'!H:H,1)/COUNTIF('baseline v4'!B:B,'master plan bk1'!B9) -> 1 | J9: completed
B10: CMMS | C10: 46048 | D10: 46157 | E10: 20-27 | F10: 0.91 | G10: =NETWORKDAYS(C10, D10, holiday!$A$2:$A$18) -> 73 | H10: =MIN(1, MAX(0, NETWORKDAYS(C10, TODAY(), holiday!$A$2:$A$18) / G10)) -> 1 | I10: =COUNTIFS('baseline v4'!B:B,B10,'baseline v4'!H:H,1)/COUNTIF('baseline v4'!B:B,'master plan bk1'!B10) -> 1 | J10: completed
B11: AI | C11: 46076 | D11: 46087 | E11: 22 | F11: 0.9 | G11: =NETWORKDAYS(C11, D11, holiday!$A$2:$A$18) -> 9 | H11: =MIN(1, MAX(0, NETWORKDAYS(C11, TODAY(), holiday!$A$2:$A$18) / G11)) -> 1 | I11: =COUNTIFS('baseline v4'!B:B,B11,'baseline v4'!H:H,1)/COUNTIF('baseline v4'!B:B,'master plan bk1'!B11) -> 1 | J11: completed
A12: MVP2: RCA | C12: =MIN(C13:D18) -> 46146 | D12: =MAX(C13:D18) -> 46269 | H12: =AVERAGE(H13:H18) -> 0.77105263 | I12: =AVERAGEA(I13:I18) -> 0.5
B13: Case Creation - Create/Edit Analysis | C13: 46146 | D13: 46213 | E13: 27-31 | F13: 0.94 | G13: =NETWORKDAYS(C13, D13, holiday!$A$2:$A$18) -> 47 | H13: =MIN(1, MAX(0, NETWORKDAYS(C13, TODAY(), holiday!$A$2:$A$18) / G13)) -> 1 | I13: =COUNTIFS('baseline v4'!B:B,B13,'baseline v4'!H:H,1)/COUNTIF('baseline v4'!B:B,'master plan bk1'!B13) -> 1 | J13: completed
B14: Case Approval | C14: 46202 | D14: 46227 | E14: 31-32 | F14: 1 | G14: =NETWORKDAYS(C14, D14, holiday!$A$2:$A$18) -> 20 | H14: =MIN(1, MAX(0, NETWORKDAYS(C14, TODAY(), holiday!$A$2:$A$18) / G14)) -> 1 | I14: =COUNTIFS('baseline v4'!B:B,B14,'baseline v4'!H:H,1)/COUNTIF('baseline v4'!B:B,'master plan bk1'!B14) -> 1 | J14: in progress
B15: Report | C15: 46216 | D15: 46241 | E15: 32-33 | F15: 0.9 | G15: =NETWORKDAYS(C15, D15, holiday!$A$2:$A$18) -> 18 | H15: =MIN(1, MAX(0, NETWORKDAYS(C15, TODAY(), holiday!$A$2:$A$18) / G15)) -> 1 | I15: =COUNTIFS('baseline v4'!B:B,B15,'baseline v4'!H:H,1)/COUNTIF('baseline v4'!B:B,'master plan bk1'!B15) -> 1 | J15: in progress
B16: RCA Dashboard. | C16: 46230 | D16: 46255 | E16: 33-34 | F16: 0.85 | G16: =NETWORKDAYS(C16, D16, holiday!$A$2:$A$18) -> 17 | H16: =MIN(1, MAX(0, NETWORKDAYS(C16, TODAY(), holiday!$A$2:$A$18) / G16)) -> 1 | I16: =COUNTIFS('baseline v4'!B:B,B16,'baseline v4'!H:H,1)/COUNTIF('baseline v4'!B:B,'master plan bk1'!B16) -> 0 | J16: in progress
B17: User Management | C17: 46244 | D17: 46269 | E17: 34-35 | F17: 0.95 | G17: =NETWORKDAYS(C17, D17, holiday!$A$2:$A$18) -> 19 | H17: =MIN(1, MAX(0, NETWORKDAYS(C17, TODAY(), holiday!$A$2:$A$18) / G17)) -> 0.52631579 | I17: =COUNTIFS('baseline v4'!B:B,B17,'baseline v4'!H:H,1)/COUNTIF('baseline v4'!B:B,'master plan bk1'!B17) -> 0 | J17: in progress
B18: Noti Email | C18: 46258 | D18: 46269 | E18: 35 | F18: 1 | G18: =NETWORKDAYS(C18, D18, holiday!$A$2:$A$18) -> 10 | H18: =MIN(1, MAX(0, NETWORKDAYS(C18, TODAY(), holiday!$A$2:$A$18) / G18)) -> 0.1 | I18: =COUNTIFS('baseline v4'!B:B,B18,'baseline v4'!H:H,1)/COUNTIF('baseline v4'!B:B,'master plan bk1'!B18) -> 0 | J18: in progress
A19: UI Improvement | C19: =MIN(C20:D26) -> 0 | D19: =MAX(C20:D26) -> 0
B20: Analysis
B21: Estimation
B22: Implementation
A23: Handover | C23: =MIN(C24:D28) -> 0 | D23: =MAX(C24:D28) -> 0
B24: Documentation
B25: Knowledge transfer

Sheet baseline v4
A1: Module | B1: Feature Name | C1: User Story ID | D1: User Story Description | E1: Sprint | F1: start | G1: end | H1: Status (1=Done, 0=Progress) | I1: Is Baseline | J1: Change Type | K1: Note | M1: Module | Feature | Sprint | T1: Baseline vs change record
A2: asm | B2: revision | C2: EAPM-906 | D2: [Improvement][Home][GeneralDetails] My Tasks - Add checked Group Permission for Waiting for Approval Box. | E2: 18 | F2: =VLOOKUP(E2, sprintday!$A$6:$C$32, 2, FALSE) -> 46027 | G2: =VLOOKUP(E2, sprintday!$A$6:$C$32, 3, FALSE) -> 46031 | H2: 1 | I2: baseline | K2: email noti | M2: Module | N2: Sprint | O2: start | P2: end | Q2: Feature Name | R2: Count of User Story Description | T2: Module | U2: Count of Is Baseline
A3: asm | B3: revision | C3: EAPM-278 | D3: [ASM][AssetStrategy] Email Notification Message - Template 2 (Review) | E3: 18 | F3: =VLOOKUP(E3, sprintday!$A$6:$C$32, 2, FALSE) -> 46027 | G3: =VLOOKUP(E3, sprintday!$A$6:$C$32, 3, FALSE) -> 46031 | H3: 1 | I3: baseline | K3: email noti | M3: asm | R3: 90 | T3: asm | U3: 90
A4: asm | B4: revision | C4: EAPM-923 | D4: [Improvement][ASM][AssetStrategy][RisksAndTasks] Risk Details - Add Description for Failure Impact + Change Field Name | E4: 18 | F4: =VLOOKUP(E4, sprintday!$A$6:$C$32, 2, FALSE) -> 46027 | G4: =VLOOKUP(E4, sprintday!$A$6:$C$32, 3, FALSE) -> 46031 | H4: 1 | I4: baseline | K4: email noti | N4: 18 | O4: 46027 | P4: 46031 | Q4: revision | R4: 8 | T4: handover | U4: 2
A5: asm | B5: revision | C5: EAPM-244 | D5: [Improvement][ASM][AssetStrategy] Strategies Table List V3. - Add column | E5: 18 | F5: =VLOOKUP(E5, sprintday!$A$6:$C$32, 2, FALSE) -> 46027 | G5: =VLOOKUP(E5, sprintday!$A$6:$C$32, 3, FALSE) -> 46031 | H5: 1 | I5: baseline | K5: email noti | N5: 19 | O5: 46034 | P5: 46045 | Q5: revision | R5: 14 | T5: rca | U5: 41
A6: asm | B6: revision | C6: EAPM-922 | D6: [ASM][AssetStrategy] Integrate FDP (GCP) - [BE] | E6: 18 | F6: =VLOOKUP(E6, sprintday!$A$6:$C$32, 2, FALSE) -> 46027 | G6: =VLOOKUP(E6, sprintday!$A$6:$C$32, 3, FALSE) -> 46031 | H6: 1 | I6: baseline | K6: integration | N6: 20 | O6: 46048 | P6: 46059 | Q6: cmms | R6: 14 | T6: ui improvement | U6: 6
A7: asm | B7: revision | C7: EAPM-919 | D7: [Improvement][ASM][AssetStrategy][RisksAndTasks] Risk/Task Panel - Change Icon Yellow Alert to Arrow Icon + Abbreviate Interval + SCE Tag | E7: 18 | F7: =VLOOKUP(E7, sprintday!$A$6:$C$32, 2, FALSE) -> 46027 | G7: =VLOOKUP(E7, sprintday!$A$6:$C$32, 3, FALSE) -> 46031 | H7: 1 | I7: baseline | K7: integration | N7: 21 | O7: 46062 | P7: 46073 | Q7: cmms | R7: 8 | T7: Grand Total | U7: 139
A8: asm | B8: revision | C8: EAPM-882 | D8: [ASM] Apply a consistent design standard to all action buttons. [FE] | E8: 18 | F8: =VLOOKUP(E8, sprintday!$A$6:$C$32, 2, FALSE) -> 46027 | G8: =VLOOKUP(E8, sprintday!$A$6:$C$32, 3, FALSE) -> 46031 | H8: 1 | I8: baseline | K8: integration | N8: 22 | O8: 46076 | P8: 46087 | Q8: ai | R8: 7
A9: asm | B9: revision | C9: EAPM-1071 | D9: [Improvement][ASM][AssetStrategy] All Table List - Change Design the shown numbers as total, select items, filter results | E9: 18 | F9: =VLOOKUP(E9, sprintday!$A$6:$C$32, 2, FALSE) -> 46027 | G9: =VLOOKUP(E9, sprintday!$A$6:$C$32, 3, FALSE) -> 46031 | H9: 1 | I9: baseline | K9: integration | Q9: cmms | R9: 4
A10: asm | B10: revision | C10: EAPM-10 | D10: [ASM][AssetStrategy][Revisions] Revision Details - Strategy Summary - Tab Summary | E10: 19 | F10: =VLOOKUP(E10, sprintday!$A$6:$C$32, 2, FALSE) -> 46034 | G10: =VLOOKUP(E10, sprintday!$A$6:$C$32, 3, FALSE) -> 46045 | H10: 1 | I10: baseline | N10: 23 | O10: 46090 | R10: 7
A11: asm | B11: revision | C11: EAPM-11 | D11: [ASM][AssetStrategy][Revisions] Revision Details - Strategy Summary - Tab Details | E11: 19 | F11: =VLOOKUP(E11, sprintday!$A$6:$C$32, 2, FALSE) -> 46034 | G11: =VLOOKUP(E11, sprintday!$A$6:$C$32, 3, FALSE) -> 46045 | H11: 1 | I11: baseline | N11: 24 | O11: 46104 | P11: 46115 | Q11: cmms | R11: 11
A12: asm | B12: revision | C12: EAPM-7 | D12: [ASM][AssetStrategy][Revisions] Revision Details - Risks and Tasks | E12: 19 | F12: =VLOOKUP(E12, sprintday!$A$6:$C$32, 2, FALSE) -> 46034 | G12: =VLOOKUP(E12, sprintday!$A$6:$C$32, 3, FALSE) -> 46045 | H12: 1 | I12: baseline | N12: 25 | O12: 46118 | P12: 46129 | Q12: cmms | R12: 5
A13: asm | B13: revision | C13: EAPM-25 | D13: [ASM][AssetStrategy][Revisions] Revision Details - Risks Details | E13: 19 | F13: =VLOOKUP(E13, sprintday!$A$6:$C$32, 2, FALSE) -> 46034 | G13: =VLOOKUP(E13, sprintday!$A$6:$C$32, 3, FALSE) -> 46045 | H13: 1 | I13: baseline | N13: 26 | O13: 46132 | P13: 46143 | Q13: cmms | R13: 6
A14: asm | B14: revision | C14: EAPM-26 | D14: [ASM][AssetStrategy][Revisions] Revision Details - Task Details | E14: 19 | F14: =VLOOKUP(E14, sprintday!$A$6:$C$32, 2, FALSE) -> 46034 | G14: =VLOOKUP(E14, sprintday!$A$6:$C$32, 3, FALSE) -> 46045 | H14: 1 | I14: baseline | N14: 27 | O14: 46146 | P14: 46157 | Q14: cmms | R14: 5
A15: asm | B15: revision | C15: EAPM-8 | D15: [ASM][AssetStrategy][Revisions] Revision Details - Risk Analysis | E15: 19 | F15: =VLOOKUP(E15, sprintday!$A$6:$C$32, 2, FALSE) -> 46034 | G15: =VLOOKUP(E15, sprintday!$A$6:$C$32, 3, FALSE) -> 46045 | H15: 1 | I15: baseline | N15: 29 | O15: 46174 | P15: 46185 | Q15: ai | R15: 1
A16: asm | B16: revision | C16: EAPM-9 | D16: [ASM][AssetStrategy][Revisions] Revision Details - Maintenance Plans | E16: 19 | F16: =VLOOKUP(E16, sprintday!$A$6:$C$32, 2, FALSE) -> 46034 | G16: =VLOOKUP(E16, sprintday!$A$6:$C$32, 3, FALSE) -> 46045 | H16: 1 | I16: baseline | M16: rca | R16: 57
A17: asm | B17: revision | C17: EAPM-1255 | D17: [ASM][AssetStrategy] Trigger an update for all data retrieved from GCP. (Location, FDP, Maintenance Plan, ...) | E17: 19 | F17: =VLOOKUP(E17, sprintday!$A$6:$C$32, 2, FALSE) -> 46034 | G17: =VLOOKUP(E17, sprintday!$A$6:$C$32, 3, FALSE) -> 46045 | H17: 1 | I17: baseline | N17: 27 | O17: 46146 | P17: 46157 | Q17: Case creation - Create/Edit Analysis | R17: 6
A18: asm | B18: revision | C18: EAPM-1302 | D18: [Improvement][Home][GeneralDetails] My Task - Apply standard design for table list | E18: 19 | F18: =VLOOKUP(E18, sprintday!$A$6:$C$32, 2, FALSE) -> 46034 | G18: =VLOOKUP(E18, sprintday!$A$6:$C$32, 3, FALSE) -> 46045 | H18: 1 | I18: baseline | N18: 28 | O18: 46160 | P18: 46171 | Q18: Case creation - Create/Edit Analysis | R18: 10
A19: asm | B19: revision | C19: EAPM-1303 | D19: [Improvement][Admin] User Management - Apply standard design for table list | E19: 19 | F19: =VLOOKUP(E19, sprintday!$A$6:$C$32, 2, FALSE) -> 46034 | G19: =VLOOKUP(E19, sprintday!$A$6:$C$32, 3, FALSE) -> 46045 | H19: 1 | I19: baseline | N19: 29 | O19: 46174 | P19: 46185 | Q19: Case creation - Create/Edit Analysis | R19: 7
A20: asm | B20: revision | C20: EAPM-1304 | D20: [Improvement][ASM][AssetStrategy][MaintenancePlan] Maintenance Plan table list - Apply standard design for table list | E20: 19 | F20: =VLOOKUP(E20, sprintday!$A$6:$C$32, 2, FALSE) -> 46034 | G20: =VLOOKUP(E20, sprintday!$A$6:$C$32, 3, FALSE) -> 46045 | H20: 1 | I20: baseline | N20: 30 | O20: 46188 | P20: 46199 | Q20: Case creation - Create/Edit Analysis | R20: 4
A21: asm | B21: revision | C21: EAPM-1392 | D21: [Improvement][ASM][AssetStrategy] Strategy Table list - Apply standard design for table list | E21: 19 | F21: =VLOOKUP(E21, sprintday!$A$6:$C$32, 2, FALSE) -> 46034 | G21: =VLOOKUP(E21, sprintday!$A$6:$C$32, 3, FALSE) -> 46045 | H21: 1 | I21: baseline | N21: 31 | O21: 46202 | P21: 46213 | Q21: case approval | R21: 2
A22: asm | B22: revision | C22: EAPM-1393 | D22: [Improvement][ASM][AssetStrategy][Revision] Revision Table list - Apply standard design for table list | E22: 19 | F22: =VLOOKUP(E22, sprintday!$A$6:$C$32, 2, FALSE) -> 46034 | G22: =VLOOKUP(E22, sprintday!$A$6:$C$32, 3, FALSE) -> 46045 | H22: 1 | I22: baseline | Q22: Case creation - Create/Edit Analysis | R22: 3
A23: asm | B23: revision | C23: EAPM-1394 | D23: [Improvement][ASM][AssetStrategy][Overview] Risk Matrix by Active Strategy Table list - Apply standard design for table list | E23: 19 | F23: =VLOOKUP(E23, sprintday!$A$6:$C$32, 2, FALSE) -> 46034 | G23: =VLOOKUP(E23, sprintday!$A$6:$C$32, 3, FALSE) -> 46045 | H23: 1 | I23: baseline | N23: 32 | O23: 46216 | P23: 46227 | Q23: case approval | R23: 14
A24: asm | B24: cmms | C24: EAPM-1150 | D24: [Improvement][ASM][AssetStrategy] Table List - Searching and Sorting field Unmitigated Matrix, Mitigated Matrix | E24: 20 | F24: =VLOOKUP(E24, sprintday!$A$6:$C$32, 2, FALSE) -> 46048 | G24: =VLOOKUP(E24, sprintday!$A$6:$C$32, 3, FALSE) -> 46059 | H24: 1 | I24: baseline | Q24: Report | R24: 1
A25: asm | B25: cmms | C25: EAPM-349 | D25: [Improvement][ASM][AssetStrategy] Excel Template File V4. #1 | E25: 20 | F25: =VLOOKUP(E25, sprintday!$A$6:$C$32, 2, FALSE) -> 46048 | G25: =VLOOKUP(E25, sprintday!$A$6:$C$32, 3, FALSE) -> 46059 | H25: 1 | I25: baseline | N25: 33 | O25: 46230 | P25: 46241 | Q25: RCA Dashboard. | R25: 2
A26: asm | B26: cmms | C26: EAPM-1309 | D26: [Improvement][ASM][AssetStrategy] Excel Template File V4. #2 | E26: 20 | F26: =VLOOKUP(E26, sprintday!$A$6:$C$32, 2, FALSE) -> 46048 | G26: =VLOOKUP(E26, sprintday!$A$6:$C$32, 3, FALSE) -> 46059 | H26: 1 | I26: baseline | Q26: Report | R26: 1
A27: asm | B27: cmms | C27: EAPM-2000 | D27: [Improvement][ASM][AssetStrategy][MaintenancePlans] Table List - Add dropdown "Work Center" | E27: 20 | F27: =VLOOKUP(E27, sprintday!$A$6:$C$32, 2, FALSE) -> 46048 | G27: =VLOOKUP(E27, sprintday!$A$6:$C$32, 3, FALSE) -> 46059 | H27: 1 | I27: baseline | N27: 34 | O27: 46244 | P27: 46255 | Q27: RCA Dashboard. | R27: 2
A28: asm | B28: cmms | C28: EAPM-1999 | D28: [Improvement][ASM][AssetStrategy][RisksAndTasks] Task Details V3. | E28: 20 | F28: =VLOOKUP(E28, sprintday!$A$6:$C$32, 2, FALSE) -> 46048 | G28: =VLOOKUP(E28, sprintday!$A$6:$C$32, 3, FALSE) -> 46059 | H28: 1 | I28: baseline | Q28: User Management | R28: 1
A29: asm | B29: cmms | C29: EAPM-1585 | D29: [Improvement][FE][ASM][RisksAndTasks] Risk Property - Add more suggestion to 3M, 6M, 12M, 18M, 24M | E29: 20 | F29: =VLOOKUP(E29, sprintday!$A$6:$C$32, 2, FALSE) -> 46048 | G29: =VLOOKUP(E29, sprintday!$A$6:$C$32, 3, FALSE) -> 46059 | H29: 1 | I29: baseline | N29: 35 | O29: 46258 | P29: 46269 | Q29: Noti Email | R29: 2
A30: asm | B30: cmms | C30: EAPM-1883 | D30: [Improvement][ASM][RisksAndTasks] - Risk Detail / Task Detail - Add more suggestion | E30: 20 | F30: =VLOOKUP(E30, sprintday!$A$6:$C$32, 2, FALSE) -> 46048 | G30: =VLOOKUP(E30, sprintday!$A$6:$C$32, 3, FALSE) -> 46059 | H30: 1 | I30: baseline | Q30: User Management | R30: 2
A31: asm | B31: cmms | C31: EAPM-2003 | D31: [Improvement][ASM][AssetStrategy][RisksAndTasks] Risk Details - Change Logic | E31: 20 | F31: =VLOOKUP(E31, sprintday!$A$6:$C$32, 2, FALSE) -> 46048 | G31: =VLOOKUP(E31, sprintday!$A$6:$C$32, 3, FALSE) -> 46059 | H31: 1 | I31: baseline | M31: handover | R31: 2
A32: asm | B32: cmms | C32: EAPM-2006 | D32: [Improvement][ASM][AssetStrategy][RisksAndTasks] Task Details - Set default ROI to "-1" | E32: 20 | F32: =VLOOKUP(E32, sprintday!$A$6:$C$32, 2, FALSE) -> 46048 | G32: =VLOOKUP(E32, sprintday!$A$6:$C$32, 3, FALSE) -> 46059 | H32: 1 | I32: baseline | N32: 42 | O32: 46356 | P32: 46367 | Q32: Document | R32: 1
A33: asm | B33: cmms | C33: EAPM-2004 | D33: [Improvement][ASM][AssetStrategy][SummaryDetails] Change default "Plant Length =20" | E33: 20 | F33: =VLOOKUP(E33, sprintday!$A$6:$C$32, 2, FALSE) -> 46048 | G33: =VLOOKUP(E33, sprintday!$A$6:$C$32, 3, FALSE) -> 46059 | H33: 1 | I33: baseline | N33: 43 | O33: 46370 | P33: 46381 | Q33: Knowledge Transfer | R33: 1
A34: asm | B34: cmms | C34: EAPM-1314 | D34: [ASM][AssetStrategy][MaintenancePlans] Integrate SAP - Mock Test JSON | E34: 20 | F34: =VLOOKUP(E34, sprintday!$A$6:$C$32, 2, FALSE) -> 46048 | G34: =VLOOKUP(E34, sprintday!$A$6:$C$32, 3, FALSE) -> 46059 | H34: 1 | I34: baseline | M34: ui improvement | R34: 6
A35: asm | B35: cmms | C35: EAPM-599 | D35: [ASM][AssetStrategy][MaintenancePlans] Table List - Submit Change Request Flow | E35: 20 | F35: =VLOOKUP(E35, sprintday!$A$6:$C$32, 2, FALSE) -> 46048 | G35: =VLOOKUP(E35, sprintday!$A$6:$C$32, 3, FALSE) -> 46059 | H35: 1 | I35: baseline | N35: 36 | O35: 46272 | P35: 46283 | Q35: Requirement & Design | R35: 1
A36: asm | B36: cmms | C36: EAPM-1305 | D36: [ASM][AssetStrategy][MaintenancePlans] Submit Change Request - Summary Action | E36: 20 | F36: =VLOOKUP(E36, sprintday!$A$6:$C$32, 2, FALSE) -> 46048 | G36: =VLOOKUP(E36, sprintday!$A$6:$C$32, 3, FALSE) -> 46059 | H36: 1 | I36: baseline | N36: 37 | O36: 46286 | P36: 46297 | Q36: Requirement & Design | R36: 1
A37: asm | B37: cmms | C37: EAPM-1799 | D37: [ASM][AssetStrategy][MaintenancePlans] Submit Change Request - Summary Action - Export Excel | E37: 20 | F37: =VLOOKUP(E37, sprintday!$A$6:$C$32, 2, FALSE) -> 46048 | G37: =VLOOKUP(E37, sprintday!$A$6:$C$32, 3, FALSE) -> 46059 | H37: 1 | I37: baseline | N37: 38 | O37: 46300 | P37: 46311 | Q37: Implementation, Testing, and Deploy | R37: 1
A38: asm | B38: cmms | C38: EAPM-2423 | D38: [ASM][AssetStrategy][MaintenancePlans] Integrate SAP - Mock Test JSON #2 | E38: 21 | F38: =VLOOKUP(E38, sprintday!$A$6:$C$32, 2, FALSE) -> 46062 | G38: =VLOOKUP(E38, sprintday!$A$6:$C$32, 3, FALSE) -> 46073 | H38: 1 | I38: baseline | N38: 39 | O38: 46314 | P38: 46325 | Q38: Implementation, Testing, and Deploy | R38: 1
A39: asm | B39: cmms | C39: EAPM-2487 | D39: [Improvement][ASM][AssetStrategy][MaintenancePlan] Converted interval value K = 000H | E39: 21 | F39: =VLOOKUP(E39, sprintday!$A$6:$C$32, 2, FALSE) -> 46062 | G39: =VLOOKUP(E39, sprintday!$A$6:$C$32, 3, FALSE) -> 46073 | H39: 1 | I39: baseline | N39: 40 | O39: 46328 | P39: 46339 | Q39: Implementation, Testing, and Deploy | R39: 1
A40: asm | B40: cmms | C40: EAPM-33 | D40: [ASM][AssetStrategy][MaintenancePlans] Submit Change Request Form - CMMS Change Request Form (RequestInfo) #1 | E40: 21 | F40: =VLOOKUP(E40, sprintday!$A$6:$C$32, 2, FALSE) -> 46062 | G40: =VLOOKUP(E40, sprintday!$A$6:$C$32, 3, FALSE) -> 46073 | H40: 1 | I40: baseline | N40: 41 | O40: 46342 | P40: 46353 | Q40: Implementation, Testing, and Deploy | R40: 1
...

Sheet summary
A1: Baseline vs Current Scope (by change type)
Q3: Module | R3: Baseline | S3: Added | T3: Split | U3: Moved | V3: Removed | W3: Total current
Q4: ASM | R4: =COUNTIFS(baseline!$A$2:$A$163,"asm",baseline!$I$2:$I$163,"baseline") -> 87 | S4: =COUNTIFS(baseline!$A$2:$A$163,"asm",baseline!$J$2:$J$163,"added") -> 3 | T4: =COUNTIFS(baseline!$A$2:$A$163,"asm",baseline!$J$2:$J$163,"split")+COUNTIFS(baseline!$A$2:$A$163,"asm",baseline!$J$2:$J$163,"Split") -> 0 | U4: =COUNTIFS(baseline!$A$2:$A$163,"asm",baseline!$J$2:$J$163,"moved")+COUNTIFS(baseline!$A$2:$A$163,"asm",baseline!$J$2:$J$163,"moved ") -> 1 | V4: =COUNTIFS(baseline!$A$2:$A$163,"asm",baseline!$J$2:$J$163,"removed") -> 0 | W4: =SUM(R4:V4) -> 91
Q5: RCA | R5: =COUNTIFS(baseline!$A$2:$A$163,"rca",baseline!$I$2:$I$163,"baseline") -> 37 | S5: =COUNTIFS(baseline!$A$2:$A$163,"rca",baseline!$J$2:$J$163,"added") -> 7 | T5: =COUNTIFS(baseline!$A$2:$A$163,"rca",baseline!$J$2:$J$163,"split")+COUNTIFS(baseline!$A$2:$A$163,"rca",baseline!$J$2:$J$163,"Split") -> 26 | U5: =COUNTIFS(baseline!$A$2:$A$163,"rca",baseline!$J$2:$J$163,"moved")+COUNTIFS(baseline!$A$2:$A$163,"rca",baseline!$J$2:$J$163,"moved ") -> 11 | V5: =COUNTIFS(baseline!$A$2:$A$163,"rca",baseline!$J$2:$J$163,"removed") -> 1 | W5: =SUM(R5:V5) -> 82
Q6: UI Improvement | R6: =COUNTIFS(baseline!$A$2:$A$163,"ui improvement",baseline!$I$2:$I$163,"baseline") -> 6 | S6: =COUNTIFS(baseline!$A$2:$A$163,"ui improvement",baseline!$J$2:$J$163,"added") -> 0 | T6: =COUNTIFS(baseline!$A$2:$A$163,"ui improvement",baseline!$J$2:$J$163,"split")+COUNTIFS(baseline!$A$2:$A$163,"ui improvement",baseline!$J$2:$J$163,"Split") -> 0 | U6: =COUNTIFS(baseline!$A$2:$A$163,"ui improvement",baseline!$J$2:$J$163,"moved")+COUNTIFS(baseline!$A$2:$A$163,"ui improvement",baseline!$J$2:$J$163,"moved ") -> 0 | V6: =COUNTIFS(baseline!$A$2:$A$163,"ui improvement",baseline!$J$2:$J$163,"removed") -> 0 | W6: =SUM(R6:V6) -> 6
Q7: Handover | R7: =COUNTIFS(baseline!$A$2:$A$163,"handover",baseline!$I$2:$I$163,"baseline") -> 2 | S7: =COUNTIFS(baseline!$A$2:$A$163,"handover",baseline!$J$2:$J$163,"added") -> 0 | T7: =COUNTIFS(baseline!$A$2:$A$163,"handover",baseline!$J$2:$J$163,"split")+COUNTIFS(baseline!$A$2:$A$163,"handover",baseline!$J$2:$J$163,"Split") -> 0 | U7: =COUNTIFS(baseline!$A$2:$A$163,"handover",baseline!$J$2:$J$163,"moved")+COUNTIFS(baseline!$A$2:$A$163,"handover",baseline!$J$2:$J$163,"moved ") -> 0 | V7: =COUNTIFS(baseline!$A$2:$A$163,"handover",baseline!$J$2:$J$163,"removed") -> 0 | W7: =SUM(R7:V7) -> 2
Q8: SAP | R8: =COUNTIFS(baseline!$A$2:$A$163,"sap",baseline!$I$2:$I$163,"baseline") -> 7 | S8: =COUNTIFS(baseline!$A$2:$A$163,"sap",baseline!$J$2:$J$163,"added") -> 1 | T8: =COUNTIFS(baseline!$A$2:$A$163,"sap",baseline!$J$2:$J$163,"split")+COUNTIFS(baseline!$A$2:$A$163,"sap",baseline!$J$2:$J$163,"Split") -> 0 | U8: =COUNTIFS(baseline!$A$2:$A$163,"sap",baseline!$J$2:$J$163,"moved")+COUNTIFS(baseline!$A$2:$A$163,"sap",baseline!$J$2:$J$163,"moved ") -> 1 | V8: =COUNTIFS(baseline!$A$2:$A$163,"sap",baseline!$J$2:$J$163,"removed") -> 0 | W8: =SUM(R8:V8) -> 9
A36: Sprint by sprint breakdown
A37: SPRINT-BY-SPRINT BREAKDOWN
A38: Sprint | B38: Date Range | C38: ASM | D38: SAP | E38: RCA | F38: UI IMP | G38: HANDOVER | H38: Total
A39: Sprint 18 | B39: 05 Jan 2026 | C39: =COUNTIFS(baseline!$A$2:$A$163,"asm",baseline!$E$2:$E$163,18) -> 8 | D39: =COUNTIFS(baseline!$A$2:$A$163,"sap",baseline!$E$2:$E$163,18) -> 0 | E39: =COUNTIFS(baseline!$A$2:$A$163,"rca",baseline!$E$2:$E$163,18) -> 0 | F39: =COUNTIFS(baseline!$A$2:$A$163,"ui improvement",baseline!$E$2:$E$163,18) -> 0 | G39: =COUNTIFS(baseline!$A$2:$A$163,"handover",baseline!$E$2:$E$163,18) -> 0 | H39: =SUM(C39:G39) -> 8
